Workbook

Sheet Summary
A1: Temporal design approach - functional requirements score summary
A2: Req. | B2: ='Design-FR'!G1 -> DDLM | C2: ='Design-FR'!H1 -> UHF | D2: ='Design-FR'!I1 -> BCDM | E2: ='Design-FR'!J1 -> SQL:2011 | F2: ='Design-FR'!K1 -> TTHHR | G2: ='Design-FR'!L1 -> T-SQL | H2: ='Design-FR'!M1 -> Anchor Model | I2: ='Design-FR'!N1 -> TTTDB | ... T2: ='Design-FR'!Y1 -> TSAPI
A3: FR1 | B3: ='Design-FR'!G20 -> 11 | C3: ='Design-FR'!H20 -> 14 | D3: ='Design-FR'!I20 -> 11.5 | E3: ='Design-FR'!J20 -> 9 | F3: ='Design-FR'!K20 -> 9.5 | G3: ='Design-FR'!L20 -> 8 | H3: ='Design-FR'!M20 -> 10 | I3: ='Design-FR'!N20 -> 6 | ... T3: ='Design-FR'!Y20 -> 7 | U3: ='Design-FR'!F20 -> Total (/18)
A4: FR2 | B4: ='Design-FR'!G28 -> 6 | C4: ='Design-FR'!H28 -> 6 | D4: ='Design-FR'!I28 -> 3 | E4: ='Design-FR'!J28 -> 2.5 | F4: ='Design-FR'!K28 -> 1 | G4: ='Design-FR'!L28 -> 3 | H4: ='Design-FR'!M28 -> 1 | I4: ='Design-FR'!N28 -> 2 | ... T4: ='Design-FR'!Y28 -> 0 | U4: ='Design-FR'!F28 -> Total (/7)
A5: FR3 | B5: ='Design-FR'!G41 -> 12 | C5: ='Design-FR'!H41 -> 5 | D5: ='Design-FR'!I41 -> 10 | E5: ='Design-FR'!J41 -> 5 | F5: ='Design-FR'!K41 -> 3.5 | G5: ='Design-FR'!L41 -> 3.5 | H5: ='Design-FR'!M41 -> 4 | I5: ='Design-FR'!N41 -> 5 | ... T5: ='Design-FR'!Y41 -> 2.5 | U5: ='Design-FR'!F41 -> Total (/12)
A6: FR4 | B6: {='Design-FR'!G55:Y55} -> 8 | C6: 8 | D6: 8 | E6: 6 | F6: 8 | G6: 6 | H6: 5 | I6: 7 | J6: 6 | K6: 6.5 | L6: 4.5 | M6: 5 | N6: 2 | O6: 4 | P6: 3.5 | Q6: 5 | R6: 5 | S6: 4 | T6: 4 | U6: ='Design-FR'!F55 -> Total (/13)
B7: ='Design-FR'!G56 -> 37 | C7: ='Design-FR'!H56 -> 33 | D7: ='Design-FR'!I56 -> 32.5 | E7: ='Design-FR'!J56 -> 22.5 | F7: ='Design-FR'!K56 -> 22 | G7: ='Design-FR'!L56 -> 20.5 | H7: ='Design-FR'!M56 -> 20 | I7: ='Design-FR'!N56 -> 20 | ... T7: ='Design-FR'!Y56 -> 13.5 | U7: ='Design-FR'!F56 -> TOTAL (/50)
A10: RDBMS - functional requirements score summary
A11: Req. | B11: ='RDBMS-FR'!G1 -> SQL:2011 | C11: =_xlfn.CONCAT('RDBMS-FR'!H1," ",'RDBMS-FR'!D60) -> Teradata 17.1 | D11: =_xlfn.CONCAT('RDBMS-FR'!I1," ",'RDBMS-FR'!D56) -> PostgreSQL 18 | E11: =_xlfn.CONCAT('RDBMS-FR'!J1," ",'RDBMS-FR'!D58) -> MariaDB 12.3.2 | F11: =_xlfn.CONCAT('RDBMS-FR'!K1," ",'RDBMS-FR'!D57) -> SAP HANA 12.1 (LUW) | G11: =_xlfn.CONCAT('RDBMS-FR'!L1," ",'RDBMS-FR'!D54) -> IBM DB2 23.26 | H11: =_xlfn.CONCAT('RDBMS-FR'!M1," ",'RDBMS-FR'!D59) -> Oracle 2026 | I11: =_xlfn.CONCAT('RDBMS-FR'!N1," ", 'RDBMS-FR'!D55) -> Microsoft SQL Server 2025 (Linux)
A12: FR1 | B12: ='RDBMS-FR'!G14 -> 6 | C12: ='RDBMS-FR'!H14 -> 9 | D12: ='RDBMS-FR'!I14 -> 8 | E12: ='RDBMS-FR'!J14 -> 11 | F12: ='RDBMS-FR'!K14 -> 9.5 | G12: ='RDBMS-FR'!L14 -> 9 | H12: ='RDBMS-FR'!M14 -> 4 | I12: ='RDBMS-FR'!N14 -> 5.5 | J12: ='RDBMS-FR'!F14 -> Total (/12)
A13: FR2 | B13: ='RDBMS-FR'!G21 -> 2.5 | C13: ='RDBMS-FR'!H21 -> 2 | D13: ='RDBMS-FR'!I21 -> 4 | E13: ='RDBMS-FR'!J21 -> 1.5 | F13: ='RDBMS-FR'!K21 -> 0 | G13: ='RDBMS-FR'!L21 -> 1.5 | H13: ='RDBMS-FR'!M21 -> 2 | I13: ='RDBMS-FR'!N21 -> 0 | J13: ='RDBMS-FR'!F21 -> Total (/6)
A14: FR3 | B14: ='RDBMS-FR'!G34 -> 5 | C14: ='RDBMS-FR'!H34 -> 12 | D14: ='RDBMS-FR'!I34 -> 2 | E14: ='RDBMS-FR'!J34 -> 4.5 | F14: ='RDBMS-FR'!K34 -> 5 | G14: ='RDBMS-FR'!L34 -> 4 | H14: ='RDBMS-FR'!M34 -> 4 | I14: ='RDBMS-FR'!N34 -> 4 | J14: ='RDBMS-FR'!F34 -> Total (/12)
A15: FR4 | B15: ='RDBMS-FR'!G48 -> 6 | C15: ='RDBMS-FR'!H48 -> 9 | D15: ='RDBMS-FR'!I48 -> 11 | E15: ='RDBMS-FR'!J48 -> 5 | F15: ='RDBMS-FR'!K48 -> 6 | G15: ='RDBMS-FR'!L48 -> 6 | H15: ='RDBMS-FR'!M48 -> 7.5 | I15: ='RDBMS-FR'!N48 -> 3.5 | J15: ='RDBMS-FR'!F48 -> Total (/13)
B16: ='RDBMS-FR'!G49 -> 19.5 | C16: ='RDBMS-FR'!H49 -> 32 | D16: ='RDBMS-FR'!I49 -> 25 | E16: ='RDBMS-FR'!J49 -> 22 | F16: ='RDBMS-FR'!K49 -> 20.5 | G16: ='RDBMS-FR'!L49 -> 20.5 | H16: ='RDBMS-FR'!M49 -> 17.5 | I16: ='RDBMS-FR'!N49 -> 13 | J16: ='RDBMS-FR'!F49 -> TOTAL (/43)

Sheet RDBMS-FR
A1: Exigence | B1: Requirement | C1: Critère | D1: Criterion | E1: Sous-critère | F1: Sub-criterion | G1: SQL:2011 | H1: Teradata | I1: PostgreSQL | J1: MariaDB | K1: SAP HANA | L1: IBM DB2 | M1: Oracle | N1: Microsoft SQL Server | O1: TOTAL (/7)
B2: ='FR-def @en'!A2 -> FR1. Temporal data structure | C2: ='FR-def @fr'!B4 -> Catégorie de temps de validité | D2: ='FR-def @en'!B4 -> Valid time category | E2: ='FR-def @fr'!C4 -> Vbe | F2: ='FR-def @en'!C4 -> Vbe | G2: ✔ | H2: ✔ | I2: ✔ | J2: ✔ | K2: ✔ | L2: ✔ | M2: ˜ | N2: ✘ | O2: =COUNTIF(H2:N2,"✔")+0.5*COUNTIF(H2:N2,"˜") -> 5.5
E3: ='FR-def @fr'!C5 -> Vbx | F3: ='FR-def @en'!C5 -> Vbx | G3: ✘ | H3: ✔ | I3: ✔ | J3: ✔ | K3: ✔ | L3: ✔ | M3: ✘ | N3: ✘ | O3: =COUNTIF(H3:N3,"✔")+0.5*COUNTIF(H3:N3,"˜") -> 5
E4: ='FR-def @fr'!C7 -> Vxx | F4: ='FR-def @en'!C6 -> Vxe | G4: ✘ | H4: ✘ | I4: ✔ | J4: ˜ | K4: ˜ | L4: ˜ | M4: ✘ | N4: ✘ | O4: =COUNTIF(H4:N4,"✔")+0.5*COUNTIF(H4:N4,"˜") -> 2.5
E5: ='FR-def @fr'!C6 -> Vxe | F5: ='FR-def @en'!C7 -> Vxx | G5: ✘ | H5: ✘ | I5: ✔ | J5: ˜ | K5: ˜ | L5: ˜ | M5: ✘ | N5: ✘ | O5: =COUNTIF(H5:N5,"✔")+0.5*COUNTIF(H5:N5,"˜") -> 2.5
C6: ='FR-def @fr'!B8 -> Catégorie de temps de transaction | D6: ='FR-def @en'!B8 -> Transaction time category | E6: ='FR-def @fr'!C8 -> Tbe | F6: ='FR-def @en'!C8 -> Tbe | G6: ✔ | H6: ✔ | I6: ˜ | J6: ✔ | K6: ✔ | L6: ✔ | M6: ˜ | N6: ✔ | O6: =COUNTIF(H6:N6,"✔")+0.5*COUNTIF(H6:N6,"˜") -> 6 | R6: Légende
E7: ='FR-def @fr'!C9 -> Tbx | F7: ='FR-def @en'!C9 -> Tbx | G7: ✔ | H7: ✔ | I7: ˜ | J7: ✔ | K7: ✔ | L7: ✔ | M7: ˜ | N7: ✔ | O7: =COUNTIF(H7:N7,"✔")+0.5*COUNTIF(H7:N7,"˜") -> 6 | R7: Symbole | S7: Description
C8: ='FR-def @en'!B10 -> Unitemporal relations | G8: ✔ | H8: ✔ | I8: ˜ | J8: ✔ | K8: ✔ | L8: ✔ | M8: ✔ | N8: ✔ | O8: =COUNTIF(H8:N8,"✔")+0.5*COUNTIF(H8:N8,"˜") -> 6.5 | R8: ✔ | S8: Critère est respecté
C9: ='FR-def @en'!B11 -> Bitemporal relations | G9: ✔ | H9: ✔ | I9: ˜ | J9: ✔ | K9: ✔ | L9: ✔ | M9: ? | N9: ✘ | O9: =COUNTIF(H9:N9,"✔")+0.5*COUNTIF(H9:N9,"˜") -> 4.5 | R9: ✘ | S9: Critère non respecté
C10: ='FR-def @en'!B12 -> Current relations | G10: ✘ | H10: ✔ | I10: ˜ | J10: ✔ | K10: ✔ | L10: ✔ | M10: ˜ | N10: ✔ | O10: =COUNTIF(H10:N10,"✔")+0.5*COUNTIF(H10:N10,"˜") -> 6 | R10: ˜ | S10: Partiellement supporté
D11: ='FR-def @en'!B13 -> History relations | G11: ✘ | H11: ✔ | I11: ˜ | J11: ✔ | K11: ✔ | L11: ˜ | M11: ˜ | N11: ✔ | O11: =COUNTIF(H11:N11,"✔")+0.5*COUNTIF(H11:N11,"˜") -> 5.5
D12: ='FR-def @en'!B14 -> Mixed relations | G12: ✔ | H12: ✔ | I12: ˜ | J12: ✔ | K12: ˜ | L12: ˜ | M12: ˜ | N12: ˜ | O12: =COUNTIF(H12:N12,"✔")+0.5*COUNTIF(H12:N12,"˜") -> 4.5
D13: ='FR-def @en'!B18 -> Suitability for non-temporal data | G13: ✘ | H13: ✘ | I13: ˜ | J13: ✔ | K13: ✘ | L13: ✘ | M13: ✘ | N13: ✘ | O13: =COUNTIF(H13:N13,"✔")+0.5*COUNTIF(H13:N13,"˜") -> 1.5 | R13: ? | S13: Incertitude ou information manquante
E14: Total (/18) | F14: Total (/12) | G14: =COUNTIF(G2:G13,"✔")+0.5*COUNTIF(G2:G13,"˜") -> 6 | H14: =COUNTIF(H2:H13,"✔")+0.5*COUNTIF(H2:H13,"˜") -> 9 | I14: =COUNTIF(I2:I13,"✔")+0.5*COUNTIF(I2:I13,"˜") -> 8 | J14: =COUNTIF(J2:J13,"✔")+0.5*COUNTIF(J2:J13,"˜") -> 11 | K14: =COUNTIF(K2:K13,"✔")+0.5*COUNTIF(K2:K13,"˜") -> 9.5 | L14: =COUNTIF(L2:L13,"✔")+0.5*COUNTIF(L2:L13,"˜") -> 9 | M14: =COUNTIF(M2:M13,"✔")+0.5*COUNTIF(M2:M13,"˜") -> 4 | N14: =COUNTIF(N2:N13,"✔")+0.5*COUNTIF(N2:N13,"˜") -> 5.5
A15: ='FR-def @fr'!A20 -> EF2. Définition des contraintes temporelles | B15: FR2. Temporal constraints | C15: ='FR-def @fr'!B20 -> Intégrité | D15: Temporal integrity | E15: ='FR-def @fr'!C20 -> Clé primaire | F15: ='FR-def @en'!C20 -> Primary key | G15: ✔ | H15: ˜ | I15: ˜ | J15: ✔ | K15: ✘ | L15: ✔ | M15: ✔ | N15: ✘ | O15: =COUNTIF(H15:N15,"✔")+0.5*COUNTIF(H15:N15,"˜") -> 4 | R15: * TODO : décrire comment le x est représenté : 9999, null ou autre
E16: ='FR-def @fr'!C21 -> Clé référentielle | F16: ='FR-def @en'!C21 -> Referential key | G16: ✔ | H16: ✘ | I16: ˜ | J16: ✘ | K16: ✘ | L16: ✘ | M16: ✔ | N16: ✘ | O16: =COUNTIF(H16:N16,"✔")+0.5*COUNTIF(H16:N16,"˜") -> 1.5 | R16: * TODO 2026-07-31 CK : distinguer les critères applicable à V, T et VB dans la FR 03 et FR 04
C17: ='FR-def @fr'!B23 -> Anomalies | D17: Temporal anomalies | E17: ='FR-def @fr'!C23 -> Redondance | F17: ='FR-def @en'!C23 -> Redundancy | G17: ˜ | H17: ˜ | I17: ✔ | J17: ˜ | K17: ✘ | L17: ˜ | M17: ✘ | N17: ✘ | O17: =COUNTIF(H17:N17,"✔")+0.5*COUNTIF(H17:N17,"˜") -> 2.5 | R17: * TODO 2026-0802 CK : add temporal aggregation operators (je crois que seul Teradata en fournit)
E18: ='FR-def @fr'!C24 -> Contradiction | F18: ='FR-def @en'!C24 -> Contradiction | G18: ✘ | H18: ˜ | I18: ✔ | J18: ✘ | K18: ✘ | L18: ✘ | M18: ✘ | N18: ✘ | O18: =COUNTIF(H18:N18,"✔")+0.5*COUNTIF(H18:N18,"˜") -> 1.5
E19: ='FR-def @fr'!C25 -> Circonlocution | F19: ='FR-def @en'!C25 -> Circumlocution | G19: ✘ | H19: ˜ | I19: ✔ | J19: ✘ | K19: ✘ | L19: ✘ | M19: ✘ | N19: ✘ | O19: =COUNTIF(H19:N19,"✔")+0.5*COUNTIF(H19:N19,"˜") -> 1.5
E20: ='FR-def @fr'!C26 -> Non compacité | F20: ='FR-def @en'!C26 -> Incompleteness | G20: ✘ | H20: ✘ | I20: ✘ | J20: ✘ | K20: ✘ | L20: ✘ | M20: ✘ | N20: ✘ | O20: =COUNTIF(H20:N20,"✔")+0.5*COUNTIF(H20:N20,"˜") -> 0
E21: Total (/6) | F21: Total (/6) | G21: =COUNTIF(G15:G20,"✔")+0.5*COUNTIF(G15:G20,"˜") -> 2.5 | H21: =COUNTIF(H15:H20,"✔")+0.5*COUNTIF(H15:H20,"˜") -> 2 | I21: =COUNTIF(I15:I20,"✔")+0.5*COUNTIF(I15:I20,"˜") -> 4 | J21: =COUNTIF(J15:J20,"✔")+0.5*COUNTIF(J15:J20,"˜") -> 1.5 | K21: =COUNTIF(K15:K20,"✔")+0.5*COUNTIF(K15:K20,"˜") -> 0 | L21: =COUNTIF(L15:L20,"✔")+0.5*COUNTIF(L15:L20,"˜") -> 1.5 | M21: =COUNTIF(M15:M20,"✔")+0.5*COUNTIF(M15:M20,"˜") -> 2 | N21: =COUNTIF(N15:N20,"✔")+0.5*COUNTIF(N15:N20,"˜") -> 0
A22: ='FR-def @fr'!#REF! -> #REF! | B22: FR3. Temporal operations | C22: ='FR-def @en'!B27 -> Historicized views | G22: ✘ | H22: ✔ | I22: ✘ | J22: ˜ | K22: ✘ | L22: ✘ | M22: ✘ | N22: ✘ | O22: =COUNTIF(H22:N22,"✔")+0.5*COUNTIF(H22:N22,"˜") -> 1.5 | R22: Symbol | S22: Description
C23: ='FR-def @fr'!B28 -> Opérateurs temporels | D23: ='FR-def @en'!B28 -> Interval and relation operators | E23: ='FR-def @fr'!C28 -> Allen | F23: ='FR-def @en'!C28 -> Allen | G23: ˜ | H23: ✔ | I23: ✔ | J23: ✘ | K23: ✘ | L23: ✘ | M23: ✔ | N23: ✘ | O23: =COUNTIF(H23:N23,"✔")+0.5*COUNTIF(H23:N23,"˜") -> 3 | R23: ✔ | S23: Criterion is met
E24: ='FR-def @fr'!C29 -> Jointures | F24: ='FR-def @en'!C29 -> Joins | G24: ˜ | H24: ✔ | I24: ˜ | J24: ✘ | K24: ✔ | L24: ✘ | M24: ✘ | N24: ✘ | O24: =COUNTIF(H24:N24,"✔")+0.5*COUNTIF(H24:N24,"˜") -> 2.5 | R24: ✘ | S24: Criterion is not met
E25: ='FR-def @fr'!C30 -> Pack | F25: ='FR-def @en'!C30 -> Pack | G25: ✘ | H25: ✔ | I25: ˜ | J25: ✘ | K25: ✘ | L25: ✘ | M25: ✘ | N25: ✘ | O25: =COUNTIF(H25:N25,"✔")+0.5*COUNTIF(H25:N25,"˜") -> 1.5 | R25: ˜ | S25: Partially supported
E26: ='FR-def @fr'!C31 -> Unpack | F26: ='FR-def @en'!C31 -> Unpack | G26: ✘ | H26: ✔ | I26: ✘ | J26: ✘ | K26: ✘ | L26: ✘ | M26: ✘ | N26: ✘ | O26: =COUNTIF(H26:N26,"✔")+0.5*COUNTIF(H26:N26,"˜") -> 1 | R26: ? | S26: Uncertainty or missing information
C27: ='FR-def @fr'!B32 -> Opérations ensemblistes | D27: Set operations | E27: ='FR-def @fr'!C32 -> Union | F27: ='FR-def @en'!C32 -> Union | G27: ✘ | H27: ✔ | I27: ✘ | J27: ✘ | K27: ✘ | L27: ✘ | M27: ✘ | N27: ✘ | O27: =COUNTIF(H27:N27,"✔")+0.5*COUNTIF(H27:N27,"˜") -> 1 | R27: Ø | S27: Not applicable, does not concern this case
E28: ='FR-def @fr'!C33 -> Différence | F28: ='FR-def @en'!C33 -> Difference | G28: ✘ | H28: ✔ | I28: ✘ | J28: ✘ | K28: ✘ | L28: ✘ | M28: ✘ | N28: ✘ | O28: =COUNTIF(H28:N28,"✔")+0.5*COUNTIF(H28:N28,"˜") -> 1
E29: ='FR-def @fr'!C34 -> Intersection | F29: ='FR-def @en'!C34 -> Intersection | G29: ✘ | H29: ✔ | I29: ✘ | J29: ✘ | K29: ✘ | L29: ✘ | M29: ✘ | N29: ✘ | O29: =COUNTIF(H29:N29,"✔")+0.5*COUNTIF(H29:N29,"˜") -> 1 | R29: * UHF 2017 : état actuel
C30: ='FR-def @fr'!B35 -> Opérations ÉMIR (CRUD) | D30: ='FR-def @en'!B35 -> Manipulation operations | E30: ='FR-def @fr'!C35 -> Évaluation | F30: ='FR-def @en'!C35 -> Evaluation | G30: ✔ | H30: ✔ | I30: ✘ | J30: ✔ | K30: ✔ | L30: ✔ | M30: ✔ | N30: ✔ | O30: =COUNTIF(H30:N30,"✔")+0.5*COUNTIF(H30:N30,"˜") -> 6
E31: ='FR-def @fr'!C36 -> Modification | F31: ='FR-def @en'!C36 -> Update | G31: ✔ | H31: ✔ | I31: ✘ | J31: ✔ | K31: ✔ | L31: ✔ | M31: ✔ | N31: ✔ | O31: =COUNTIF(H31:N31,"✔")+0.5*COUNTIF(H31:N31,"˜") -> 6
E32: ='FR-def @fr'!C37 -> Insertion | F32: ='FR-def @en'!C37 -> Insertion | G32: ✔ | H32: ✔ | I32: ✘ | J32: ✔ | K32: ✔ | L32: ✔ | M32: ✔ | N32: ✔ | O32: =COUNTIF(H32:N32,"✔")+0.5*COUNTIF(H32:N32,"˜") -> 6
E33: ='FR-def @fr'!C38 -> Retrait | F33: ='FR-def @en'!C38 -> Deletion | G33: ✔ | H33: ✔ | I33: ✘ | J33: ✔ | K33: ✔ | L33: ✔ | M33: ✘ | N33: ✔ | O33: =COUNTIF(H33:N33,"✔")+0.5*COUNTIF(H33:N33,"˜") -> 5
E34: Total (/13) | F34: Total (/12) | G34: =COUNTIF(G22:G33,"✔")+0.5*COUNTIF(G22:G33,"˜") -> 5 | H34: =COUNTIF(H22:H33,"✔")+0.5*COUNTIF(H22:H33,"˜") -> 12 | I34: =COUNTIF(I22:I33,"✔")+0.5*COUNTIF(I22:I33,"˜") -> 2 | J34: =COUNTIF(J22:J33,"✔")+0.5*COUNTIF(J22:J33,"˜") -> 4.5 | K34: =COUNTIF(K22:K33,"✔")+0.5*COUNTIF(K22:K33,"˜") -> 5 | L34: =COUNTIF(L22:L33,"✔")+0.5*COUNTIF(L22:L33,"˜") -> 4 | M34: =COUNTIF(M22:M33,"✔")+0.5*COUNTIF(M22:M33,"˜") -> 4 | N34: =COUNTIF(N22:N33,"✔")+0.5*COUNTIF(N22:N33,"˜") -> 4
A35: ='FR-def @fr'!A39 -> EF4. Mise en œuvre temporelle | B35: FR4. Temporal implementation | C35: ='FR-def @fr'!B39 -> Gestion du temps de transaction | D35: ='FR-def @en'!B39 -> Transaction time management | E35: ='FR-def @fr'!C39 -> log file | F35: ='FR-def @en'!C39 -> log file | G35: ✘ | H35: ✔ | I35: ? | J35: ? | K35: ✘ | L35: ✔ | M35: ✔ | N35: ˜ | O35: =COUNTIF(H35:N35,"✔")+0.5*COUNTIF(H35:N35,"˜") -> 3.5
E36: ='FR-def @fr'!C40 -> commit time | F36: ='FR-def @en'!C40 -> commit time | G36: ✔ | H36: ✘ | I36: ? | J36: ✔ | K36: ✔ | L36: ✘ | M36: ✘ | N36: ✘ | O36: =COUNTIF(H36:N36,"✔")+0.5*COUNTIF(H36:N36,"˜") -> 2
C37: ='FR-def @fr'!B41 -> Méthode d’implémentation | D37: ='FR-def @en'!B41 -> Implementation method | E37: ='FR-def @fr'!C41 -> Directement sur un SGBD | F37: ='FR-def @en'!C41 -> Directly on a DBMS | G37: ✘ | H37: ✔ | I37: ✔ | J37: ✔ | K37: ✔ | L37: ✔ | M37: ✔ | N37: ✔ | O37: =COUNTIF(H37:N37,"✔")+0.5*COUNTIF(H37:N37,"˜") -> 7
E38: ='FR-def @fr'!C42 -> Extension d'un SGBD | F38: ='FR-def @en'!C42 -> Extension of a DBMS | G38: ✔ | H38: ✘ | I38: ✔ | J38: ✘ | K38: ✘ | L38: ✘ | M38: ✔ | N38: ✘ | O38: =COUNTIF(H38:N38,"✔")+0.5*COUNTIF(H38:N38,"˜") -> 2
C39: ='FR-def @fr'!B43 -> Procédures d’alimentation | D39: ='FR-def @en'!B43 -> Loading procedures | E39: ='FR-def @fr'!C43 -> Utilisation des procédures stockées | F39: ='FR-def @en'!C43 -> Use of stored procedures | G39: ✘ | H39: ✘ | I39: ✔ | J39: ? | K39: ✘ | L39: ✘ | M39: ✘ | N39: ✘ | O39: =COUNTIF(H39:N39,"✔")+0.5*COUNTIF(H39:N39,"˜") -> 1
E40: ='FR-def @fr'!C44 -> Utilisation des triggers | F40: ='FR-def @en'!C44 -> Use of triggers | G40: ✔ | H40: ✔ | I40: ✔ | J40: ✘ | K40: ✔ | L40: ✘ | M40: ✘ | N40: ✘ | O40: =COUNTIF(H40:N40,"✔")+0.5*COUNTIF(H40:N40,"˜") -> 3
...

Sheet Design-FR
A1: Exigence | B1: Requirement | C1: Critère | D1: Criterion | E1: Sous-critère | F1: Sub-criterion | G1: DDLM | H1: UHF | I1: BCDM | J1: SQL:2011 | K1: TTHHR | L1: T-SQL | M1: Anchor Model | N1: TTTDB | O1: Chronon | P1: TF-ORM | Q1: CME | R1: CLTS | S1: TEERM | T1: Chronus II | U1: PMTV | V1: TEER | W1: RMTD-6NF | X1: TempR-PDM | Y1: TSAPI | Z1: TOTAL (/19)
A2: ='FR-def @fr'!A2 -> EF1. Modélisation structurelle | B2: FR1. Temporal data structure | C2: ='FR-def @fr'!B2 -> Structure d’historicisation | D2: ='FR-def @en'!B2 -> Historicization approach | E2: ='FR-def @fr'!C2 -> Tuple | F2: ='FR-def @en'!C2 -> Tuple | G2: ✘ | H2: ✔ | I2: ✔ | J2: ✔ | K2: ✔ | L2: ✔ | M2: ✘ | N2: ✔ | O2: ✔ | P2: ✘ | Q2: ✔ | R2: ✘ | S2: ✔ | T2: ✔ | U2: ✔ | V2: ✔ | W2: ✘ | X2: ✔ | Y2: ✔ | Z2: =COUNTIF(G2:Y2,"✔")+0.5*COUNTIF(G2:Y2,"˜") -> 14 | AB2: =19/2 -> 9.5
E3: ='FR-def @fr'!C3 -> Attribut | F3: ='FR-def @en'!C3 -> Attribute | G3: ✔ | H3: ✔ | I3: ✘ | J3: ✘ | K3: ✔ | L3: ✘ | M3: ✔ | N3: ✘ | O3: ✔ | P3: ✔ | Q3: ˜ | R3: ✔ | S3: ✘ | T3: ✘ | U3: ˜ | V3: ✘ | W3: ✔ | X3: ✘ | Y3: ✔ | Z3: =COUNTIF(G3:Y3,"✔")+0.5*COUNTIF(G3:Y3,"˜") -> 10
C4: ='FR-def @fr'!B4 -> Catégorie de temps de validité | D4: ='FR-def @en'!B4 -> Valid time category | E4: ='FR-def @fr'!C4 -> Vbe | F4: ='FR-def @en'!C4 -> Vbe | G4: ✔ | H4: ✔ | I4: ✔ | J4: ✔ | K4: ✔ | L4: ✔ | M4: ˜ | N4: ✘ | O4: ✔ | P4: ✔ | Q4: ✔ | R4: ? | S4: ✔ | T4: ✔ | U4: ✔ | V4: ✔ | W4: ? | X4: ✔ | Y4: ✘ | Z4: =COUNTIF(G4:Y4,"✔")+0.5*COUNTIF(G4:Y4,"˜") -> 14.5
E5: ='FR-def @fr'!C5 -> Vbx | F5: ='FR-def @en'!C5 -> Vbx | G5: ✔ | H5: ✔ | I5: ✔ | J5: ✘ | K5: ✘ | L5: ✘ | M5: ˜ | N5: ✘ | O5: ✔ | P5: ✔ | Q5: ✔ | R5: ✔ | S5: ? | T5: ✔ | U5: ? | V5: ✔ | W5: ✔ | X5: ✘ | Y5: ✘ | Z5: =COUNTIF(G5:Y5,"✔")+0.5*COUNTIF(G5:Y5,"˜") -> 10.5
E6: ='FR-def @fr'!C7 -> Vxx | F6: ='FR-def @en'!C6 -> Vxe | G6: ✘ | H6: ✔ | I6: ✘ | J6: ✘ | K6: ✘ | L6: ✘ | M6: ✘ | N6: ✘ | O6: ✘ | P6: ✘ | Q6: ✘ | R6: ✘ | S6: ✘ | T6: ✘ | U6: ✘ | V6: ✘ | W6: ✘ | X6: ✘ | Y6: ✘ | Z6: =COUNTIF(G6:Y6,"✔")+0.5*COUNTIF(G6:Y6,"˜") -> 1
E7: ='FR-def @fr'!C6 -> Vxe | F7: ='FR-def @en'!C7 -> Vxx | G7: ✘ | H7: ✘ | I7: ✘ | J7: ✘ | K7: ✘ | L7: ✘ | M7: ✘ | N7: ✘ | O7: ✘ | P7: ✘ | Q7: ✘ | R7: ✘ | S7: ? | T7: ✘ | U7: ✘ | V7: ✘ | W7: ✘ | X7: ✘ | Y7: ✘ | Z7: =COUNTIF(G7:Y7,"✔")+0.5*COUNTIF(G7:Y7,"˜") -> 0
C8: ='FR-def @fr'!B8 -> Catégorie de temps de transaction | D8: ='FR-def @en'!B8 -> Transaction time category | E8: ='FR-def @fr'!C8 -> Tbe | F8: ='FR-def @en'!C8 -> Tbe | G8: ✔ | H8: ✔ | I8: ✔ | J8: ✔ | K8: ✘ | L8: ✔ | M8: ✔ | N8: ✘ | O8: ✘ | P8: ✔ | Q8: ✘ | R8: ✘ | S8: ✔ | T8: ✘ | U8: ✔ | V8: ✘ | W8: ✘ | X8: ✘ | Y8: ✔ | Z8: =COUNTIF(G8:Y8,"✔")+0.5*COUNTIF(G8:Y8,"˜") -> 10 | AC8: Légende
E9: ='FR-def @fr'!C9 -> Tbx | F9: ='FR-def @en'!C9 -> Tbx | G9: ✘ | H9: ✔ | I9: ✔ | J9: ✔ | K9: ✘ | L9: ✔ | M9: ✔ | N9: ✔ | O9: ✘ | P9: ✔ | Q9: ✘ | R9: ✘ | S9: ? | T9: ✘ | U9: ✔ | V9: ✔ | W9: ✔ | X9: ✔ | Y9: ✘ | Z9: =COUNTIF(G9:Y9,"✔")+0.5*COUNTIF(G9:Y9,"˜") -> 11 | AC9: Symbole | AD9: Description
C10: ='FR-def @en'!B10 -> Unitemporal relations | G10: ✔ | H10: ✔ | I10: ✔ | J10: ✔ | K10: ✔ | L10: ✔ | M10: ✔ | N10: ✔ | O10: ✔ | P10: ✘ | Q10: ✔ | R10: ✔ | S10: ✔ | T10: ✔ | U10: ✘ | V10: ✘ | W10: ✔ | X10: ✘ | Y10: ✔ | Z10: =COUNTIF(G10:Y10,"✔")+0.5*COUNTIF(G10:Y10,"˜") -> 15 | AC10: ✔ | AD10: Critère est respecté
C11: ='FR-def @en'!B11 -> Bitemporal relations | G11: ✔ | H11: ✔ | I11: ✔ | J11: ✔ | K11: ✘ | L11: ✔ | M11: ✔ | N11: ✘ | O11: ✘ | P11: ✔ | Q11: ✘ | R11: ✘ | S11: ✔ | T11: ✘ | U11: ✔ | V11: ✔ | W11: ✔ | X11: ✔ | Y11: ✘ | Z11: =COUNTIF(G11:Y11,"✔")+0.5*COUNTIF(G11:Y11,"˜") -> 12 | AC11: ✘ | AD11: Critère non respecté
C12: ='FR-def @en'!B12 -> Current relations | G12: ✔ | H12: ✔ | I12: ✔ | J12: ✘ | K12: ✔ | L12: ✔ | M12: ✘ | N12: ✔ | O12: ✘ | P12: ✘ | Q12: ✔ | R12: ✔ | S12: ✘ | T12: ✘ | U12: ✘ | V12: ✘ | W12: ✘ | X12: ✘ | Y12: ✔ | Z12: =COUNTIF(G12:Y12,"✔")+0.5*COUNTIF(G12:Y12,"˜") -> 9 | AC12: ˜ | AD12: Partiellement supporté
C13: ='FR-def @en'!B13 -> History relations | G13: ✔ | H13: ✔ | I13: ✔ | J13: ✘ | K13: ✔ | L13: ✔ | M13: ✘ | N13: ✘ | O13: ✘ | P13: ✘ | Q13: ✔ | R13: ✔ | S13: ✘ | T13: ✘ | U13: ✘ | V13: ✘ | W13: ✘ | X13: ✘ | Y13: ✔ | Z13: =COUNTIF(G13:Y13,"✔")+0.5*COUNTIF(G13:Y13,"˜") -> 8 | AC13: ? | AD13: Incertitude ou information manquante
C14: ='FR-def @en'!B14 -> Mixed relations | G14: ✘ | H14: ✘ | I14: ✔ | J14: ✔ | K14: ✘ | L14: ✘ | M14: ✔ | N14: ✔ | O14: ✔ | P14: ✔ | Q14: ✘ | R14: ✘ | S14: ✔ | T14: ✔ | U14: ✔ | V14: ✔ | W14: ✔ | X14: ✔ | Y14: ✘ | Z14: =COUNTIF(G14:Y14,"✔")+0.5*COUNTIF(G14:Y14,"˜") -> 12 | AC14: Ø | AD14: Non applicable, ne concerne pas ce cas
C15: ='FR-def @fr'!B15 -> Forme normale des relations | D15: Normal form of relations | E15: ='FR-def @fr'!C15 -> 1FN | F15: ='FR-def @en'!C15 -> 1NF | G15: ✘ | H15: ✘ | I15: ✘ | J15: ✔ | K15: ✘ | L15: ? | M15: ✘ | N15: ? | O15: ? | P15: ✘ | Q15: ? | R15: ✔ | S15: ✔ | T15: ✔ | U15: ? | V15: ? | W15: ✘ | X15: ✔ | Y15: ? | Z15: =COUNTIF(G15:Y15,"✔")+0.5*COUNTIF(G15:Y15,"˜") -> 5
E16: ='FR-def @fr'!C16 -> 5FN | F16: ='FR-def @en'!C16 -> 5NF | G16: ✔ | H16: ✘ | I16: ✔ | J16: ✘ | K16: ✔ | L16: ? | M16: ✘ | N16: ✘ | O16: ? | P16: ? | Q16: ? | R16: ✘ | S16: ✔ | T16: ✘ | U16: ? | V16: ? | W16: ✘ | X16: ✔ | Y16: ? | Z16: =COUNTIF(G16:Y16,"✔")+0.5*COUNTIF(G16:Y16,"˜") -> 5
E17: ='FR-def @fr'!C17 -> 6FN | F17: ='FR-def @en'!C17 -> 6NF | G17: ✔ | H17: ✔ | I17: ✘ | J17: ✘ | K17: ✔ | L17: ✘ | M17: ✔ | N17: ✘ | O17: ✘ | P17: ? | Q17: ✘ | R17: ✘ | S17: ✔ | T17: ✘ | U17: ✘ | V17: ✘ | W17: ✔ | X17: ✘ | Y17: ✘ | Z17: =COUNTIF(G17:Y17,"✔")+0.5*COUNTIF(G17:Y17,"˜") -> 6
C18: Suitability for non-temporal data | G18: ˜ | H18: ✔ | I18: ˜ | J18: ✘ | K18: ✔ | L18: ✘ | M18: ✔ | N18: ✔ | O18: ✘ | P18: ✔ | Q18: ✔ | R18: ✔ | S18: ✔ | T18: ✔ | U18: ✘ | V18: ˜ | W18: ✘ | X18: ✔ | Y18: ✔ | Z18: =COUNTIF(G18:Y18,"✔")+0.5*COUNTIF(G18:Y18,"˜") -> 12.5
C19: ='FR-def @en'!B19 -> Resilience to change | G19: ˜ | H19: ✔ | I19: ✘ | J19: ✔ | K19: ˜ | L19: ✘ | M19: ✔ | N19: ✘ | O19: ✘ | P19: ✘ | Q19: ˜ | R19: ✔ | S19: ✘ | T19: ? | U19: ✔ | V19: ˜ | W19: ✔ | X19: ˜ | Y19: ✘ | Z19: =COUNTIF(G19:Y19,"✔")+0.5*COUNTIF(G19:Y19,"˜") -> 8.5
E20: Total (/18) | F20: Total (/18) | G20: =COUNTIF(G2:G19,"✔")+0.5*COUNTIF(G2:G19,"˜") -> 11 | H20: =COUNTIF(H2:H19,"✔")+0.5*COUNTIF(H2:H19,"˜") -> 14 | I20: =COUNTIF(I2:I19,"✔")+0.5*COUNTIF(I2:I19,"˜") -> 11.5 | J20: =COUNTIF(J2:J19,"✔")+0.5*COUNTIF(J2:J19,"˜") -> 9 | K20: =COUNTIF(K2:K19,"✔")+0.5*COUNTIF(K2:K19,"˜") -> 9.5 | L20: =COUNTIF(L2:L19,"✔")+0.5*COUNTIF(L2:L19,"˜") -> 8 | M20: =COUNTIF(M2:M19,"✔")+0.5*COUNTIF(M2:M19,"˜") -> 10 | N20: =COUNTIF(N2:N19,"✔")+0.5*COUNTIF(N2:N19,"˜") -> 6 | ... Y20: =COUNTIF(Y2:Y19,"✔")+0.5*COUNTIF(Y2:Y19,"˜") -> 7
A21: ='FR-def @fr'!A20 -> EF2. Définition des contraintes temporelles | B21: FR2. Temporal constraints | C21: ='FR-def @fr'!B20 -> Intégrité | D21: Temporal integrity | E21: ='FR-def @fr'!C20 -> Clé primaire | F21: ='FR-def @en'!C20 -> Primary key | G21: ✔ | H21: ✔ | I21: ✔ | J21: ✔ | K21: ✔ | L21: ✔ | M21: ✔ | N21: ✔ | O21: ✔ | P21: ✘ | Q21: ✘ | R21: ✔ | S21: ✔ | T21: ✘ | U21: ✘ | V21: ✘ | W21: ✔ | X21: ✔ | Y21: ✘ | Z21: =COUNTIF(G21:Y21,"✔")+0.5*COUNTIF(G21:Y21,"˜") -> 13
E22: ='FR-def @fr'!C21 -> Clé référentielle | F22: ='FR-def @en'!C21 -> Referential key | G22: ✔ | H22: ✔ | I22: ✔ | J22: ✔ | K22: ? | L22: ✔ | M22: ✘ | N22: ✔ | O22: ✔ | P22: ✘ | Q22: ✘ | R22: ˜ | S22: ✔ | T22: ✘ | U22: ✘ | V22: ✘ | W22: ✘ | X22: ✘ | Y22: ✘ | Z22: =COUNTIF(G22:Y22,"✔")+0.5*COUNTIF(G22:Y22,"˜") -> 8.5
C23: Temporal Functional Dependency | G23: ✘ | H23: ✘ | I23: ✘ | J23: ✘ | K23: ✘ | L23: ✘ | M23: ✘ | N23: ✘ | O23: ✘ | P23: ✘ | Q23: ✘ | R23: ✘ | S23: ✔ | T23: ✘ | U23: ✘ | V23: ✘ | W23: ✘ | X23: ✘ | Y23: ✘ | Z23: =COUNTIF(G23:Y23,"✔")+0.5*COUNTIF(G23:Y23,"˜") -> 1
C24: ='FR-def @fr'!B23 -> Anomalies | D24: Temporal anomalies | E24: ='FR-def @fr'!C23 -> Redondance | F24: ='FR-def @en'!C23 -> Redundancy | G24: ✔ | H24: ✔ | I24: ✔ | J24: ˜ | K24: ✘ | L24: ✘ | M24: ✘ | N24: Ø | O24: ✘ | P24: ✘ | Q24: ✔ | R24: ✘ | S24: ˜ | T24: ✘ | U24: ✘ | V24: ˜ | W24: ˜ | X24: ✘ | Y24: Ø | Z24: =COUNTIF(G24:Y24,"✔")+0.5*COUNTIF(G24:Y24,"˜") -> 6
E25: ='FR-def @fr'!C24 -> Contradiction | F25: ='FR-def @en'!C24 -> Contradiction | G25: ✔ | H25: ✔ | I25: ✘ | J25: ✘ | K25: ✘ | L25: ✔ | M25: ✘ | N25: Ø | O25: ✘ | P25: ˜ | Q25: ✘ | R25: ✘ | S25: ˜ | T25: ✘ | U25: ✘ | V25: ✘ | W25: ✘ | X25: ✘ | Y25: Ø | Z25: =COUNTIF(G25:Y25,"✔")+0.5*COUNTIF(G25:Y25,"˜") -> 4
E26: ='FR-def @fr'!C25 -> Circonlocution | F26: ='FR-def @en'!C25 -> Circumlocution | G26: ✔ | H26: ✔ | I26: ✘ | J26: ✘ | K26: ✘ | L26: ✘ | M26: ✘ | N26: Ø | O26: ✘ | P26: ✘ | Q26: ✘ | R26: ✘ | S26: ✘ | T26: ✘ | U26: ✘ | V26: ✘ | W26: ✘ | X26: ✘ | Y26: Ø | Z26: =COUNTIF(G26:Y26,"✔")+0.5*COUNTIF(G26:Y26,"˜") -> 2
E27: ='FR-def @fr'!C26 -> Non compacité | F27: ='FR-def @en'!C26 -> Incompleteness | G27: ✔ | H27: ✔ | I27: ✘ | J27: ✘ | K27: ✘ | L27: ✘ | M27: ✘ | N27: Ø | O27: ✘ | P27: ✘ | Q27: ✘ | R27: ✘ | S27: ✘ | T27: ✘ | U27: ✘ | V27: ✘ | W27: ✘ | X27: ✘ | Y27: Ø | Z27: =COUNTIF(G27:Y27,"✔")+0.5*COUNTIF(G27:Y27,"˜") -> 2
E28: Total (/6) | F28: Total (/7) | G28: =COUNTIF(G21:G27,"✔")+0.5*COUNTIF(G21:G27,"˜") -> 6 | H28: =COUNTIF(H21:H27,"✔")+0.5*COUNTIF(H21:H27,"˜") -> 6 | I28: =COUNTIF(I21:I27,"✔")+0.5*COUNTIF(I21:I27,"˜") -> 3 | J28: =COUNTIF(J21:J27,"✔")+0.5*COUNTIF(J21:J27,"˜") -> 2.5 | K28: =COUNTIF(K21:K27,"✔")+0.5*COUNTIF(K21:K27,"˜") -> 1 | L28: =COUNTIF(L21:L27,"✔")+0.5*COUNTIF(L21:L27,"˜") -> 3 | M28: =COUNTIF(M21:M27,"✔")+0.5*COUNTIF(M21:M27,"˜") -> 1 | N28: =COUNTIF(N21:N27,"✔")+0.5*COUNTIF(N21:N27,"˜") -> 2 | ... Y28: =COUNTIF(Y21:Y27,"✔")+0.5*COUNTIF(Y21:Y27,"˜") -> 0
A29: ='FR-def @fr'!#REF! -> #REF! | B29: FR3. Temporal operations | C29: ='FR-def @en'!B27 -> Historicized views | G29: ✔ | H29: ✔ | I29: ✔ | J29: ✘ | K29: ✘ | L29: ✘ | M29: ✘ | N29: ✔ | O29: ✘ | P29: ? | Q29: ✘ | R29: ✘ | S29: ✘ | T29: ✘ | U29: ✘ | V29: ✘ | W29: ✘ | X29: ✘ | Y29: ✘ | Z29: =COUNTIF(G29:Y29,"✔")+0.5*COUNTIF(G29:Y29,"˜") -> 4 | AC29: Symbol | AD29: Description
C30: ='FR-def @fr'!B28 -> Opérateurs temporels | D30: ='FR-def @en'!B28 -> Interval and relation operators | E30: ='FR-def @fr'!C28 -> Allen | F30: ='FR-def @en'!C28 -> Allen | G30: ✔ | H30: ✔ | I30: ✔ | J30: ˜ | K30: ✘ | L30: ✘ | M30: ✘ | N30: ✘ | O30: ✘ | P30: ✘ | Q30: ✘ | R30: ✘ | S30: ✘ | T30: ✔ | U30: ✘ | V30: ✘ | W30: ✘ | X30: ✘ | Y30: ✘ | Z30: =COUNTIF(G30:Y30,"✔")+0.5*COUNTIF(G30:Y30,"˜") -> 4.5 | AC30: ✔ | AD30: Criterion is met
E31: ='FR-def @fr'!C29 -> Jointures | F31: ='FR-def @en'!C29 -> Joins | G31: ✔ | H31: ✘ | I31: ✔ | J31: ˜ | K31: ˜ | L31: ✔ | M31: ✘ | N31: ✘ | O31: ✘ | P31: ˜ | Q31: ✘ | R31: ✘ | S31: ✘ | T31: ✔ | U31: ✔ | V31: ✘ | W31: ✘ | X31: ✘ | Y31: ˜ | Z31: =COUNTIF(G31:Y31,"✔")+0.5*COUNTIF(G31:Y31,"˜") -> 7 | AC31: ✘ | AD31: Criterion is not met
E32: ='FR-def @fr'!C30 -> Pack | F32: ='FR-def @en'!C30 -> Pack | G32: ✔ | H32: ✔ | I32: ✔ | J32: ✘ | K32: ✘ | L32: ✘ | M32: ✘ | N32: ✘ | O32: ✔ | P32: ✘ | Q32: ✔ | R32: ✘ | S32: ✘ | T32: ✔ | U32: ✘ | V32: ✘ | W32: ✘ | X32: ✘ | Y32: ✘ | Z32: =COUNTIF(G32:Y32,"✔")+0.5*COUNTIF(G32:Y32,"˜") -> 6 | AC32: ˜ | AD32: Partially supported
E33: ='FR-def @fr'!C31 -> Unpack | F33: ='FR-def @en'!C31 -> Unpack | G33: ✔ | H33: ✔ | I33: ✘ | J33: ✘ | K33: ✘ | L33: ✘ | M33: ✘ | N33: ✘ | O33: ✔ | P33: ✘ | Q33: ✘ | R33: ✘ | S33: ✘ | T33: ✘ | U33: ✘ | V33: ✘ | W33: ✘ | X33: ✘ | Y33: ✘ | Z33: =COUNTIF(G33:Y33,"✔")+0.5*COUNTIF(G33:Y33,"˜") -> 3 | AC33: ? | AD33: Uncertainty or missing information
C34: ='FR-def @fr'!B32 -> Opérations ensemblistes | D34: Set operations | E34: ='FR-def @fr'!C32 -> Union | F34: ='FR-def @en'!C32 -> Union | G34: ✔ | H34: ✔ | I34: ✔ | J34: ✘ | K34: ✘ | L34: ✘ | M34: ✘ | N34: ✘ | O34: ✘ | P34: ✘ | Q34: ✘ | R34: ✘ | S34: ✘ | T34: ✘ | U34: ✔ | V34: ✘ | W34: ✘ | X34: ✘ | Y34: ✘ | Z34: =COUNTIF(G34:Y34,"✔")+0.5*COUNTIF(G34:Y34,"˜") -> 4 | AC34: Ø | AD34: Not applicable, does not concern this case
E35: ='FR-def @fr'!C33 -> Différence | F35: ='FR-def @en'!C33 -> Difference | G35: ✔ | H35: ✘ | I35: ✔ | J35: ✘ | K35: ✘ | L35: ✘ | M35: ✘ | N35: ✘ | O35: ✘ | P35: ✘ | Q35: ✘ | R35: ✘ | S35: ✘ | T35: ✘ | U35: ✔ | V35: ✘ | W35: ✘ | X35: ✘ | Y35: ✘ | Z35: =COUNTIF(G35:Y35,"✔")+0.5*COUNTIF(G35:Y35,"˜") -> 3
E36: ='FR-def @fr'!C34 -> Intersection | F36: ='FR-def @en'!C34 -> Intersection | G36: ✔ | H36: ✘ | I36: ✘ | J36: ✘ | K36: ✘ | L36: ✘ | M36: ✘ | N36: ✘ | O36: ✘ | P36: ✘ | Q36: ✘ | R36: ✘ | S36: ✘ | T36: ✘ | U36: ✔ | V36: ✘ | W36: ✘ | X36: ✘ | Y36: ✘ | Z36: =COUNTIF(G36:Y36,"✔")+0.5*COUNTIF(G36:Y36,"˜") -> 2
C37: ='FR-def @fr'!B35 -> Opérations ÉMIR (CRUD) | D37: ='FR-def @en'!B35 -> Manipulation operations | E37: ='FR-def @fr'!C35 -> Évaluation | F37: ='FR-def @en'!C35 -> Evaluation | G37: ✔ | H37: ✘ | I37: ✔ | J37: ✔ | K37: ✔ | L37: ✔ | M37: ✔ | N37: ✔ | O37: ✔ | P37: ˜ | Q37: ˜ | R37: ˜ | S37: ✘ | T37: ✔ | U37: ✘ | V37: ˜ | W37: ✘ | X37: ✘ | Y37: ˜ | Z37: =COUNTIF(G37:Y37,"✔")+0.5*COUNTIF(G37:Y37,"˜") -> 11.5
E38: ='FR-def @fr'!C36 -> Modification | F38: ='FR-def @en'!C36 -> Update | G38: ✔ | H38: ✘ | I38: ✔ | J38: ✔ | K38: ✔ | L38: ˜ | M38: ✔ | N38: ✔ | O38: ˜ | P38: ˜ | Q38: ˜ | R38: ˜ | S38: ✘ | T38: ✘ | U38: ✘ | V38: ˜ | W38: ✘ | X38: ✘ | Y38: ˜ | Z38: =COUNTIF(G38:Y38,"✔")+0.5*COUNTIF(G38:Y38,"˜") -> 9.5
E39: ='FR-def @fr'!C37 -> Insertion | F39: ='FR-def @en'!C37 -> Insertion | G39: ✔ | H39: ✘ | I39: ✔ | J39: ✔ | K39: ✔ | L39: ˜ | M39: ✔ | N39: ✔ | O39: ˜ | P39: ✔ | Q39: ✔ | R39: ˜ | S39: ✘ | T39: ✘ | U39: ✘ | V39: ˜ | W39: ✘ | X39: ✘ | Y39: ˜ | Z39: =COUNTIF(G39:Y39,"✔")+0.5*COUNTIF(G39:Y39,"˜") -> 10.5
E40: ='FR-def @fr'!C38 -> Retrait | F40: ='FR-def @en'!C38 -> Deletion | G40: ✔ | H40: ✘ | I40: ✔ | J40: ✔ | K40: ✘ | L40: ˜ | M40: ✔ | N40: ✔ | O40: ˜ | P40: ˜ | Q40: ? | R40: ˜ | S40: ✘ | T40: ✘ | U40: ✘ | V40: ˜ | W40: ✘ | X40: ✘ | Y40: ˜ | Z40: =COUNTIF(G40:Y40,"✔")+0.5*COUNTIF(G40:Y40,"˜") -> 8
...

Sheet Design-NFR
A1: Exigence | B1: Requirement | C1: Critère | D1: Criterion | E1: Sous-critère | F1: Sub-criterion | G1: DDLM | H1: UHF | I1: BCDM | J1: SQL:2011 | K1: TTHHR | L1: T-SQL | M1: Anchor Model | N1: TTTDB | O1: Chronon | P1: TF-ORM | Q1: CME | R1: CLTS | S1: TEERM | T1: Chronus II | U1: PMTV | V1: TEER | W1: RMTD-6NF | X1: TempR-PDM | Y1: TSAPI | Z1: TOTAL (/19)
A2: ='NFR-def @fr'!A2 -> ENF1. Disponibilité et maintenance | B2: ='NFR-def @en'!A2 -> NFR1. Availability and maintenance | C2: ='NFR-def @fr'!B2 -> Mode de distribution | D2: Distribution mode | E2: ='NFR-def @fr'!C2 -> Open source | F2: Open source | G2: ✘ | H2: ✔ | I2: ✘ | J2: Ø | K2: ✘ | L2: ✔ | M2: ✔ | N2: ✘ | O2: ? | P2: ✘ | Q2: ✘ | R2: ✘ | S2: ? | T2: ✘ | U2: ? | V2: ? | W2: ✘ | X2: ? | Y2: ✘ | Z2: =COUNTIF(G2:Y2,"✔")+0.5*COUNTIF(G2:Y2,"˜") -> 3
E3: ='NFR-def @fr'!C3 -> Licence commerciale | F3: Commercial license | G3: ✘ | H3: ✘ | I3: ✘ | J3: Ø | K3: ✘ | L3: ✘ | M3: ✘ | N3: ✘ | O3: ? | P3: ✘ | Q3: ✘ | R3: ✘ | S3: ? | T3: ✘ | U3: ? | V3: ? | W3: ✘ | X3: ? | Y3: ✘ | Z3: =COUNTIF(G3:Y3,"✔")+0.5*COUNTIF(G3:Y3,"˜") -> 0
C4: ='NFR-def @fr'!B4 -> Support et maintenance | D4: Support and maintenance | E4: ='NFR-def @fr'!C4 -> Documentation technique | F4: Technical documentation | G4: ✘ | H4: ˜ | I4: ✘ | J4: ✔ | K4: ˜ | L4: ✔ | M4: ✔ | N4: ˜ | O4: ? | P4: ˜ | Q4: ˜ | R4: ✘ | S4: ? | T4: ˜ | U4: ? | V4: ? | W4: ✘ | X4: ? | Y4: ˜ | Z4: =COUNTIF(G4:Y4,"✔")+0.5*COUNTIF(G4:Y4,"˜") -> 6.5
E5: ='NFR-def @fr'!C5 -> Tutoriels et exemples | F5: Tutorials and examples | G5: ✘ | H5: ✘ | I5: ✘ | J5: ✔ | K5: ˜ | L5: ✔ | M5: ✔ | N5: ˜ | O5: ? | P5: ˜ | Q5: ˜ | R5: ✘ | S5: ? | T5: ✘ | U5: ? | V5: ? | W5: ✘ | X5: ? | Y5: ✘ | Z5: =COUNTIF(G5:Y5,"✔")+0.5*COUNTIF(G5:Y5,"˜") -> 5
E6: ='NFR-def @fr'!C6 -> Mises à jour régulières | F6: Regular updates | G6: ✘ | H6: ✘ | I6: ✘ | J6: ✔ | K6: ✘ | L6: ✘ | M6: ✔ | N6: ✘ | O6: ? | P6: ✘ | Q6: ✘ | R6: ✘ | S6: ? | T6: ✘ | U6: ? | V6: ? | W6: ✘ | X6: ? | Y6: ✘ | Z6: =COUNTIF(G6:Y6,"✔")+0.5*COUNTIF(G6:Y6,"˜") -> 2
C7: ='NFR-def @fr'!B7 -> Support communautaire | D7: Community support | E7: ='NFR-def @fr'!C7 -> Communauté active | F7: Active community | G7: ✘ | H7: ✔ | I7: ✘ | J7: ✘ | K7: ✘ | L7: ✘ | M7: ✔ | N7: ✘ | O7: ? | P7: ✘ | Q7: ✘ | R7: ✘ | S7: ? | T7: ✘ | U7: ? | V7: ? | W7: ✘ | X7: ? | Y7: ✘ | Z7: =COUNTIF(G7:Y7,"✔")+0.5*COUNTIF(G7:Y7,"˜") -> 2 | AC7: Légende
E8: ='NFR-def @fr'!C8 -> Plateformes communautaires | F8: Community platforms | G8: ✘ | H8: ✘ | I8: ✘ | J8: ✘ | K8: ✘ | L8: GitHub | M8: Forum | N8: ✘ | O8: ? | P8: ✘ | Q8: ✘ | R8: ✘ | S8: ? | T8: ✘ | U8: ? | V8: ? | W8: ✘ | X8: ? | Y8: ✘ | Z8: =COUNTIF(G8:Y8,"✔")+0.5*COUNTIF(G8:Y8,"˜") -> 0 | AC8: Symbole | AD8: Description
C9: ='NFR-def @fr'!B9 -> Technologie de développement | D9: Development technology | E9: ='NFR-def @fr'!C9 -> Langage de programmation | F9: Programming language | G9: ✘ | H9: Java | I9: ✘ | J9: SQL | K9: ? | L9: C | M9: Java Script | N9: ? | O9: ? | P9: Delphi | Q9: Java | R9: ? | S9: ? | T9: Java | U9: ? | V9: ? | W9: ✘ | X9: ? | Y9: React.js, Spring boot | Z9: =COUNTIF(G9:Y9,"✔")+0.5*COUNTIF(G9:Y9,"˜") -> 0 | AC9: ✔ | AD9: Critère est respecté
F10: Nb. Total* (/7) | G10: =COUNTIF(G2:G9,"✔")+0.5*COUNTIF(G2:G9,"˜") -> 0 | H10: =COUNTIF(H2:H9,"✔")+0.5*COUNTIF(H2:H9,"˜") -> 2.5 | I10: =COUNTIF(I2:I9,"✔")+0.5*COUNTIF(I2:I9,"˜") -> 0 | J10: =COUNTIF(J2:J9,"✔")+0.5*COUNTIF(J2:J9,"˜") -> 3 | K10: =COUNTIF(K2:K9,"✔")+0.5*COUNTIF(K2:K9,"˜") -> 1 | L10: =COUNTIF(L2:L9,"✔")+0.5*COUNTIF(L2:L9,"˜") -> 3 | M10: =COUNTIF(M2:M9,"✔")+0.5*COUNTIF(M2:M9,"˜") -> 5 | N10: =COUNTIF(N2:N9,"✔")+0.5*COUNTIF(N2:N9,"˜") -> 1 | O10: _ | P10: =COUNTIF(P2:P9,"✔")+0.5*COUNTIF(P2:P9,"˜") -> 1 | Q10: =COUNTIF(Q2:Q9,"✔")+0.5*COUNTIF(Q2:Q9,"˜") -> 1 | R10: =COUNTIF(R2:R9,"✔")+0.5*COUNTIF(R2:R9,"˜") -> 0 | S10: _ | T10: =COUNTIF(T2:T9,"✔")+0.5*COUNTIF(T2:T9,"˜") -> 0.5 | U10: _ | V10: _ | W10: =COUNTIF(W2:W9,"✔")+0.5*COUNTIF(W2:W9,"˜") -> 0 | X10: _ | Y10: =COUNTIF(Y2:Y9,"✔")+0.5*COUNTIF(Y2:Y9,"˜") -> 0.5 | AC10: ✘ | AD10: Critère non respecté
A11: ='NFR-def @fr'!A10 -> ENF2. Compatibilité et interopérabilité | B11: ='NFR-def @en'!A10 -> NFR2. Compatibility and interoperability | C11: ='NFR-def @fr'!B10 -> SGBD supportés | D11: Supported DBMS | E11: ='NFR-def @fr'!C10 -> PostgreSQL | F11: PostgreSQL | G11: ✘ | H11: ✔ | I11: ✔ | J11: ˜ | K11: ✔ | L11: ✔ | M11: ✔ | N11: ✔ | O11: ? | P11: ✘ | Q11: ✘ | R11: ✘ | S11: ? | T11: ˜ | U11: ? | V11: ? | W11: ? | X11: ? | Y11: ✘ | Z11: =COUNTIF(G11:Y11,"✔")+0.5*COUNTIF(G11:Y11,"˜") -> 7 | AC11: ˜ | AD11: Partiellement supporté
E12: IBM Db2 | F12: IBM Db2 | G12: ✘ | H12: ✘ | I12: ✔ | J12: ˜ | K12: ✘ | L12: ✘ | M12: ✘ | N12: ✘ | O12: ? | P12: ✘ | Q12: ✘ | R12: ✘ | S12: ? | T12: ˜ | U12: ? | V12: ? | W12: ? | X12: ? | Y12: ✘ | Z12: =COUNTIF(G12:Y12,"✔")+0.5*COUNTIF(G12:Y12,"˜") -> 2 | AC12: ? | AD12: Incertitude ou information manquante
E13: MS SQL | F13: MS SQL | G13: ✘ | H13: ✘ | I13: ✔ | J13: ˜ | K13: ✘ | L13: ✘ | M13: ✔ | N13: ✘ | O13: ? | P13: ✘ | Q13: ✘ | R13: ✘ | S13: ? | T13: ˜ | U13: ? | V13: ? | W13: ? | X13: ? | Y13: ✘ | Z13: =COUNTIF(G13:Y13,"✔")+0.5*COUNTIF(G13:Y13,"˜") -> 3 | AC13: Ø | AD13: Non applicable, ne concerne pas ce cas
E14: MariaDB | F14: MariaDB | G14: ✘ | H14: ✘ | I14: ✔ | J14: ˜ | K14: ✘ | L14: ✘ | M14: ✘ | N14: ✘ | O14: ? | P14: ✘ | Q14: ✘ | R14: ✘ | S14: ? | T14: ˜ | U14: ? | V14: ? | W14: ? | X14: ? | Y14: ✘ | Z14: =COUNTIF(G14:Y14,"✔")+0.5*COUNTIF(G14:Y14,"˜") -> 2
E15: Oracle | F15: Oracle | G15: ✘ | H15: ✘ | I15: ✔ | J15: ˜ | K15: ✘ | L15: ✘ | M15: ✔ | N15: ✘ | O15: ✔ | P15: ✔ | Q15: ✔ | R15: ✔ | S15: ? | T15: ˜ | U15: v | V15: ? | W15: ✔ | X15: ? | Y15: ✘ | Z15: =COUNTIF(G15:Y15,"✔")+0.5*COUNTIF(G15:Y15,"˜") -> 8
F16: Nb. Total*(/5) | G16: =COUNTIF(G11:G15,"✔")+0.5*COUNTIF(G11:G15,"˜") -> 0 | H16: =COUNTIF(H11:H15,"✔")+0.5*COUNTIF(H11:H15,"˜") -> 1 | I16: =COUNTIF(I11:I15,"✔")+0.5*COUNTIF(I11:I15,"˜") -> 5 | J16: =COUNTIF(J11:J15,"✔")+0.5*COUNTIF(J11:J15,"˜") -> 2.5 | K16: =COUNTIF(K11:K15,"✔")+0.5*COUNTIF(K11:K15,"˜") -> 1 | L16: =COUNTIF(L11:L15,"✔")+0.5*COUNTIF(L11:L15,"˜") -> 1 | M16: =COUNTIF(M11:M15,"✔")+0.5*COUNTIF(M11:M15,"˜") -> 3 | N16: =COUNTIF(N11:N15,"✔")+0.5*COUNTIF(N11:N15,"˜") -> 1 | O16: _ | P16: =COUNTIF(P11:P15,"✔")+0.5*COUNTIF(P11:P15,"˜") -> 1 | Q16: =COUNTIF(Q11:Q15,"✔")+0.5*COUNTIF(Q11:Q15,"˜") -> 1 | R16: =COUNTIF(R11:R15,"✔")+0.5*COUNTIF(R11:R15,"˜") -> 1 | S16: _ | T16: =COUNTIF(T11:T15,"✔")+0.5*COUNTIF(T11:T15,"˜") -> 2.5 | U16: _ | V16: _ | W16: =COUNTIF(W11:W15,"✔")+0.5*COUNTIF(W11:W15,"˜") -> 1 | X16: _ | Y16: =COUNTIF(Y11:Y15,"✔")+0.5*COUNTIF(Y11:Y15,"˜") -> 0 | Z16: =COUNTIF(G16:Y16,"✔")+0.5*COUNTIF(G16:Y16,"˜") -> 0
A17: ='NFR-def @fr'!A15 -> ENF3. Langage de requête supporté | B17: ='NFR-def @en'!A15 -> NFR3. Supported query languages | G17: SQL | H17: SQL | I17: SQL | J17: SQL | K17: SQL | L17: SQL | M17: SQL | N17: SQL | O17: SQL | P17: TF-ORM Query Language | Q17: SQL TSQL | R17: SQL | S17: ? | T17: Chronus Query Language | U17: ? | V17: SQL | W17: SQL | X17: ? | Y17: SQL | Z17: =COUNTIF(G17:Y17,"✔")+0.5*COUNTIF(G17:Y17,"˜") -> 0 | AC17: Legend
A18: ='NFR-def @fr'!A16 -> ENF4. Test et validation | B18: ='NFR-def @en'!A16 -> NFR4. Testing and validation | C18: ='NFR-def @en'!B16 -> Functional tests | D18: {='NFR-def @en'!B16:C16} -> Functional tests | E18: 0 | G18: ? | H18: ? | I18: Ø | J18: Ø | K18: ? | L18: ✔ | M18: ? | N18: ? | O18: ? | P18: ? | Q18: ? | R18: ? | S18: ? | T18: ? | U18: ? | V18: ? | W18: ✘ | X18: ? | Y18: ? | Z18: =COUNTIF(G18:Y18,"✔")+0.5*COUNTIF(G18:Y18,"˜") -> 1 | AC18: Symbol | AD18: Description
C19: ='NFR-def @en'!B17 -> Performance tests | D19: {='NFR-def @en'!B17:C17} -> Performance tests | E19: 0 | G19: ✘ | H19: ✘ | I19: ✔ | J19: Ø | K19: ✔ | L19: ✔ | M19: ✔ | N19: ✔ | O19: ? | P19: ✘ | Q19: ✘ | R19: ✔ | S19: ? | T19: ? | U19: ? | V19: ? | W19: ✔ | X19: ? | Y19: ? | Z19: =COUNTIF(G19:Y19,"✔")+0.5*COUNTIF(G19:Y19,"˜") -> 7 | AC19: ✔ | AD19: Criterion is met
F20: Nb. Total* (/2) | G20: =COUNTIF(G18:G19,"✔")+0.5*COUNTIF(G18:G19,"˜") -> 0 | H20: =COUNTIF(H18:H19,"✔")+0.5*COUNTIF(H18:H19,"˜") -> 0 | I20: =COUNTIF(I18:I19,"✔")+0.5*COUNTIF(I18:I19,"˜") -> 1 | J20: =COUNTIF(J18:J19,"✔")+0.5*COUNTIF(J18:J19,"˜") -> 0 | K20: =COUNTIF(K18:K19,"✔")+0.5*COUNTIF(K18:K19,"˜") -> 1 | L20: =COUNTIF(L18:L19,"✔")+0.5*COUNTIF(L18:L19,"˜") -> 2 | M20: =COUNTIF(M18:M19,"✔")+0.5*COUNTIF(M18:M19,"˜") -> 1 | N20: =COUNTIF(N18:N19,"✔")+0.5*COUNTIF(N18:N19,"˜") -> 1 | O20: _ | P20: =COUNTIF(P18:P19,"✔")+0.5*COUNTIF(P18:P19,"˜") -> 0 | Q20: =COUNTIF(Q18:Q19,"✔")+0.5*COUNTIF(Q18:Q19,"˜") -> 0 | R20: =COUNTIF(R18:R19,"✔")+0.5*COUNTIF(R18:R19,"˜") -> 1 | S20: _ | T20: =COUNTIF(T18:T19,"✔")+0.5*COUNTIF(T18:T19,"˜") -> 0 | U20: _ | V20: _ | W20: =COUNTIF(W18:W19,"✔")+0.5*COUNTIF(W18:W19,"˜") -> 1 | X20: _ | Y20: =COUNTIF(Y18:Y19,"✔")+0.5*COUNTIF(Y18:Y19,"˜") -> 0 | Z20: =COUNTIF(G20:Y20,"✔")+0.5*COUNTIF(G20:Y20,"˜") -> 0 | AC20: ✘ | AD20: Criterion is not met
F21: Nb. Total* (/15) | G21: =G10+G16+G20 -> 0 | H21: =H10+H16+H20 -> 3.5 | I21: =I10+I16+I20 -> 6 | J21: =J10+J16+J20 -> 5.5 | K21: =K10+K16+K20 -> 3 | L21: =L10+L16+L20 -> 6 | M21: =M10+M16+M20 -> 9 | N21: =N10+N16+N20 -> 3 | O21: _ | P21: =P10+P16+P20 -> 2 | Q21: =Q10+Q16+Q20 -> 2 | R21: =R10+R16+R20 -> 2 | S21: _ | T21: =T10+T16+T20 -> 3 | U21: _ | V21: _ | W21: =W10+W16+W20 -> 2 | X21: _ | Y21: =Y10+Y16+Y20 -> 0.5 | AC21: ˜ | AD21: Partially supported
AC22: ? | AD22: Uncertainty or missing information
AC23: Ø | AD23: Not applicable, does not concern this case

Sheet FR-def @en
A1: Requirement | B1: Criterion | C1: Sub-criterion | D1: Description | E1: Example
A2: FR1. Temporal data structure | B2: Historicization approach | C2: Tuple | D2: In tuple timestamping, each tuple in a temporal relation is associated with a temporal attribute that represents the time dimension of the whole tuple.
C3: Attribute | D3: In attribute timestamping, each attribute in a temporal relation is associated with a temporal attribute that represents the time dimension of the attribute value.
B4: Valid time category | C4: Vbe | D4: A fully defined time interval is an interval where the begin point and the end point are specified for valid time.
C5: Vbx | D5: An indefinite end valid time is an interval where only the begin point is specified.
C6: Vxe | D6: An indefinite begin valid time is an interval where only the end point is specified.
C7: Vxx | D7: A fully indefinite valid time is an interval where the begin and the end point are unspecified.
B8: Transaction time category | C8: Tbe | D8: A fully defined time interval is an interval where the begin point and the end point are specified for transaction time.
C9: Tbx | D9: An indefinite end transaction time is an interval where only the begin point is specified.
B10: Unitemporal relations | D10: Relations that support a single temporal dimension, either the valid time or the transaction time.
B11: Bitemporal relations | D11: Relations that support two temporal dimensions, the valid time and the transaction time.
B12: Current relations | D12: Relations representing the latest (most recent) state of an entity.
B13: History relations | D13: Relations representing the previous states of an entity.
B14: Mixed relations | D14: Relations representing the evolution of an entity, including both its current state and previous states.
B15: Normal form of relations | C15: 1NF | D15: Relations in which all attributes are atomic (excluding nested relations).
C16: 5NF | D16: Relations composed in such a way as to eliminate any redundancy associated with join dependencies, without any loss of information during reconstruction.
C17: 6NF | D17: Relations composed with a key, one non-key attribute, and the temporal attributes.
B18: Suitability for non-temporal data | D18: The model’s ability to handle data without a temporal dimension (non temporal relations), particularly attributes whose values do not change over time.
B19: Resilience to change | D19: The model’s ability to adapt to new functional requirements by extending the schema (e.g., adding new attributes) without disrupting existing structures and constraints.
A20: FR2. Temporal constraints | B20: Temporal integrity | C20: Primary key | D20: A temporal primary key ensures that the same values for key attributes do not have overlapping time intervals.
C21: Referential key | D21: A temporal referential key ensures that an interval of a tuple in the reference relation is included in the interval of the corresponding tuple in the referenced relation.
B22: Temporal Functional Dependency | D22: Using temporal functional dependencies to structure the historicized schema or to define temporal constraints.
B23: Temporal anomalies | C23: Redundancy | D23: A temporal redundancy anomaly occurs if a relation contains more than one tuple that shares the same values for a given set of attributes at a time point.
C24: Contradiction | D24: A temporal contradiction anomaly occurs if more than one tuple in a relation exists that shares, at a time point, the same values for a subset of the attributes, but has different values for the remaining attributes.
C25: Circumlocution | D25: A temporal circumlocution anomaly occurs if more than one tuple is in a relation exist with the same values for a subset of the attributes and their time interval meets.
C26: Incompleteness | D26: A temporal incompleteness anomaly between two relations occurs if for a tuple in one relation there is no corresponding tuple in the other relation that shares the same values for a given set of attributes at a time point.
A27: FR3. Temporal operations | B27: Historicized views | D27: Construction of relation representing the temporal evolution of the data by combining the different time partitions.
B28: Interval and relation operators | C28: Allen | D28: Application of Allen operators to express, manipulate, and compare time intervals.
C29: Joins | D29: Application of temporal joins that incorporate conditions on temporal dimensions in order to join tuples whose time intervals satisfy a given temporal predicate.
C30: Pack | D30: Application of the Pack operator (aka, fold, coalesce) to merge tuples with the same values for non-temporal attributes when their temporal intervals overlap.
C31: Unpack | D31: Application of the Unpack operator to decompose a tuple containing an interval-type attribute into several elementary tuples.
B32: Set operations | C32: Union | D32: Combining the tuples from two relations, including the union of the interval values (the set of all points from interval i1 and i2).
C33: Difference | D33: Subtracting the tuples found in a relation from those of another including the difference of interval values (the set of all points that are in interval i1 but not in interval i2).
C34: Intersection | D34: Extracting the commun tuples from two relations including the intersection of interval values (the set of all points that are in both intervals).
B35: Manipulation operations | C35: Evaluation | D35: An operation that selects a set of tuples from a temporal relation, taking into account the associated temporal constraints and conditions.
C36: Update | D36: An operation that changes the values of a tuple by adding a new tuple, possibly accompanied by an adjustment to the temporal attribute of one or more tuples.
C37: Insertion | D37: An operation that adds a new tuple to a temporal relation by explicitly associating the required temporal attributes manually or automatically (validity time and/or transaction time).
C38: Deletion | D38: An operation that removes a tuple. In a valid time relation, a portion of the valid time interval may be updated. In a transaction relation or a bitemporal relation, the end point of the transaction time attribute is updated.
A39: FR4. Temporal implementation | B39: Transaction time management | C39: log file | D39: Transaction time is handled using on the DBMS transaction logs.
C40: commit time | D40: Transaction time is handled using the transaction commit time.
...

Sheet FR-def @fr
A1: ='Design-FR'!A1 -> Exigence | B1: Critère | C1: Sous-critère | D1: Description | E1: Exemple
A2: EF1. Modélisation structurelle | B2: Structure d’historicisation | C2: Tuple | D2: Association des intervalles à chaque tuple d’une relation.
C3: Attribut | D3: Association des intervalles aux valeurs d’attributs afin d’historiciser chaque attribut indépendamment, sans duplication des autres attributs.
B4: Catégorie de temps de validité | C4: Vbe | D4: Intervalle de validité déterminé : le début et la fin de validité sont explicitement déterminés.
C5: Vbx | D5: Intervalle de validité avec la borne de fin inconnue (début explicite, fin inconnue).
C6: Vxe | D6: Intervalle de validité avec la borne de début inconnue (début inconnu, fin explicite).
C7: Vxx | D7: Intervalle de validité indéterminé : le début et la fin sont inconnus.
B8: Catégorie de temps de transaction | C8: Tbe | D8: Intervalle de transaction déterminé : le début et la fin de présence de l’enregistrement dans la BD sont explicitement déterminés.
C9: Tbx | D9: Intervalle de transaction avec la borne de fin inconnue : début explicite et la fin est inconnue etant que l’enregistrement n’est pas supprimé ou remplacé.
B10: Relations unitemporelles | D10: Relations prenant en charge une seule dimension temporelle, soit le temps de validité, soit le temps de transaction.
B11: Relations bitemporelles | D11: Relations prenant en charge simultanément deux dimensions temporelles : le temps de validité et le temps de transaction.
B12: Relations courantes | D12: Relations représentant le dernier état (le plus récent) d’une entité.
B13: Relations historiques | D13: Relations représentant l’historique de l’état d’une entité. Les intervalles peuvent être à propos du passé, du présent et du futur.
B14: Relations mixtes | D14: Relations représentant l’évolution d’une entité, incluant à la fois l’état courant et les états historique.
B15: Forme normale des relations | C15: 1FN | D15: Relations dans lesquelles tous les attributs sont atomiques.
C16: 5FN | D16: Relations décomposées de manière à éliminer toute redondance liée aux dépendances de jointure, sans perte d’information lors de la recomposition.
C17: 6FN | D17: Relations décomposées au niveau des attributs, où chaque relation représente un fait élémentaire associé à une clé et, un attribut non clé et un attribut temporel.
B18: Adéquation aux données non temporelles | D18: Capacité du modèle à gérer des données sans dimension temporelle, notamment les attributs dont les valeurs n’évoluent pas dans le temps, et à les distinguer des données historicisées.
B19: Résistance aux changements | D19: Capacité du modèle à évoluer face à de nouvelles exigences fonctionnelles par extension du schéma (par exemple ajout de nouveaux attributs), sans remise en cause des structures existantes.
A20: EF2. Définition des contraintes temporelles | B20: Intégrité | C20: Clé primaire | D20: Définition de clés primaires garantissant l’unicité des faits, y compris en présence d’attributs temporels.
C21: Clé référentielle | D21: Définition de clés référentielles assurant la cohérence référentielle entre entités, y compris sur les dimensions temporelles, en respectant la validité temporelle des données référencées.
B22: Utilisation de DFT | D22: Utilisation des dépendances fonctionnelles temporelles pour définir et structurer le schéma historicisé. Les DFT peuvent être équivalentes à une relation temporelle unique, évitant ainsi la décomposition d’une relation en sous-partitions.
B23: Anomalies | C23: Redondance | D23: Capacité du modèle à détecter la présence de plusieurs tuples portant les mêmes données, dont les intervalles temporels se chevauchent, entraînant une duplication inutile de l’information.
C24: Contradiction | D24: Capacité du modèle à détecter la présence de plusieurs tuples partageant la même clé mais des valeurs différentes pour un même attribut, alors que leurs intervalles temporels se chevauchent partiellement ou totalement.
C25: Circonlocution | D25: Capacité du modèle à détecter des situations où plusieurs tuples décrivent la même information avec des intervalles temporels qui se se jouxtent, nécessitant leur combinaison pour reconstituer un état continu.
C26: Non compacité | D26: Capacité du modèle à détecter des situations où l’intervalle temporel du tuple référencé n’est pas représenté par un seul tuple, mais par l’union de plusieurs tuples, alors que la contrainte de compacité (denseness) exige une égalité d’intervalle entre le tuple source et le tuple référencé.
A27: EF3. Gestion des opérations temporelles​ | B27: Génération des vues historicisées | D27: Génération de vues permettant de reconstruire l’évolution temporelle des données, en combinant les différentes partitions temporelles par des opérations d’union.
B28: Opérateurs temporels | C28: Allen | D28: Application des opérateurs d’Allen pour exprimer, manipuler et comparer des intervalles temporels (Before, After, Overlaps, Meets, During, Equals, Begins, Ends).
C29: Jointures | D29: Application de jointures temporelles intégrant des conditions sur les dimensions temporelles, afin de relier des tuples dont les intervalles satisfont une relation temporelle donnée.
C30: Pack | D30: Application de l’opérateur Pack permettant de fusionner des tuples ayant les mêmes valeurs pour les attributs non temporels, lorsque leurs intervalles temporels se chevauchent.
C31: Unpack | D31: Application de l’opérateur Unpack permettant de décomposer un tuple contenant un attribut de type intervalle en plusieurs tuples élémentaires, de manière à garantir une cardinalité 1 pour chaque attribut temporel.
B32: Opérations ensemblistes | C32: Union | D32: Combinaison des tuples de deux relations structurellement compatibles, avec l'union des valeurs des intervalles.
C33: Différence | D33: Soustraction des tuples d'une relation des tuples d'une autre incluant la soustraction des intervalles (l'ensemble de tous les points qui appartiennent à l'intervalle i1 mais pas à l'intervalle i2)
C34: Intersection | D34: Extraction des tuples présents dans deux relations (permettant d'identifier les éléments communs à deux critères distincts) incluant l'intersection des valeurs des intervalles ().
B35: Opérations ÉMIR (CRUD) | C35: Évaluation | D35: Opération de sélection un ensemble de tuples d’une relation temporelle, en tenant compte des contraintes et conditions temporelles associées.
C36: Modification | D36: Opération qui change des valeurs d'un tuple par l’ajout d’un nouveau tuple, éventuellement accompagné de l’ajustement d'attribut temporel d'un ou de plusieurs tuples.
C37: Insertion | D37: Opération qui ajoute un nouveau tuple dans une relation temporelle, en associant explicitement les attributs temporels requis manuellement ou automatiquement (temps de validité et/ou temps de transaction).
C38: Retrait | D38: Opération qui supprime un tuple. Dans une relation temporelle validité, une partie de l'intervalle de validité peut être mise à jour. Dans une relation temporelle de transaction ou une relation bitemporelle, le point de fin de l'intervalle de transaction est mis à jour.
A39: EF4. Mise en œuvre temporelle | B39: Gestion du temps de transaction | C39: log file | D39: Gestion du temps de transaction reposant sur l’exploitation des journaux de transaction du SGBD.
C40: commit time | D40: Gestion du temps de transaction basée sur l’horodatage du commit des transactions par le SGBD.
...

Sheet NFR-def @en
A1: Requirement | B1: Criterion | C1: Sub-criterion | D1: Description | E1: Example
A2: NFR1. Availability and maintenance | B2: Distribution mode | C2: Open source | D2: Source code is freely accessible, allowing modification, adaptation and redistribution under the terms of the license. | E2: Project published on GitHub with MIT or Apache 2.0 license, allowing commercial use and the creation of derivatives.
C3: Commercial license | D3: Proprietary solution requiring the purchase of a license for its use and deployment. | E3: Commercial software with different license levels (enterprise, developer, academic) determining the accessible features.
B4: Support and maintenance | C4: Technical documentation | D4: Availability of comprehensive documentation covering the architecture, API, features and deployment procedures. | E4: Online documentation with installation guides, complete API reference, architecture diagrams and commented code examples.
C5: Tutorials and examples | D5: Presence of practical guides and concrete examples to facilitate the adoption and use of the solution. | E5: Collection of progressive tutorials ranging from basic installation to advanced use cases, with code examples and test database.
C6: Regular updates | D6: Frequency and quality of corrective and evolutionary updates of the solution. | E6: Quarterly release cycle with monthly bug fixes, detailed release notes and long-term support policy.
B7: Community support | C7: Active community | D7: Presence of a community of users and developers contributing to the support and evolution of the solution. | E7: Active forum with more than 100 messages per month, regular contributions to the code, and meetups organized by users.
C8: Community platforms | D8: Existence of communication and mutual support channels between users and developers. | E8: Dedicated Stack Overflow tag, Discord/Slack channel, mailing list, and GitHub repository with active issue tracking.
B9: Development technology | C9: Programming language | D9: Programming language(s) used to implement the solution, which may influence performance, portability and ease of extension. | E9: Java, Python, C++, JavaScript, etc.
A10: NFR2. Compatibility and interoperability | B10: Supported DBMS | C10: PostgreSQL | D10: Implementation of the solution on different database management systems ensuring compatibility of temporal features. | E10: Type Range for the management of temporal periods.
C11: IBM Db2 | E11: Business Time and System Time for the management of valid time and transaction time.
C12: MS SQL
C13: MariaDB | E13: System-Versioned Tables
C14: Oracle | E14: Flashback Data Archive
A15: NFR3. Supported query languages | D15: Query languages supported by the solution to query and manipulate temporal data, whether SQL and its temporal extensions or proprietary languages specific to the tool. | E15: SQL:2011, TSQL, TF-ORM Query Language, etc.
A16: NFR4. Testing and validation | B16: Functional tests | D16: Verification that the implemented temporal model behaves correctly according to the expected scenarios, covering all temporal operations and integrity rules. | E16: The modification of a tuple generates a new version with the correct validity or transaction period, the old version remains accessible, and an attempt to insert overlapping periods is rejected by the tool.
B17: Performance tests | D17: Evaluation of response times during temporal queries on large volumes of data. | E17: Measurement of the response time of a temporal query for detecting temporal anomalies using fold/unfold and another using window functions.

Sheet NFR-def @fr
A1: Exigence | B1: Critère | C1: Sous-critère | D1: Description | E1: Exemple
A2: ENF1. Disponibilité et maintenance | B2: Mode de distribution | C2: Open source | D2: Solution dont le code source est accessible librement, permettant la modification, l'adaptation et la redistribution selon les termes de la licence. | E2: Projet publié sur GitHub avec licence MIT ou Apache 2.0, permettant une utilisation commerciale et la création de dérivés.
C3: Licence commerciale | D3: Solution propriétaire nécessitant l'achat d'une licence pour son utilisation et son déploiement. | E3: Logiciel commercial avec différents niveaux de licence (entreprise, développeur, académique) déterminant les fonctionnalités accessibles.
B4: Support et maintenance | C4: Documentation technique | D4: Disponibilité de documentation exhaustive couvrant l'architecture, l'API, les fonctionnalités et les procédures de déploiement. | E4: Documentation en ligne avec guides d'installation, référence API complète, diagrammes d'architecture et exemples de code commentés.
C5: Tutoriels et exemples | D5: Présence de guides pratiques et d'exemples concrets pour faciliter la prise en main et l'utilisation de la solution. | E5: Collection de tutoriels progressifs allant de l'installation de base à des cas d'usage avancés, avec exemples de code et base de données de test.
C6: Mises à jour régulières | D6: Fréquence et qualité des mises à jour correctives et évolutives de la solution. | E6: Cycle de release trimestriel avec corrections de bugs mensuelles, notes de version détaillées et politique de support à long terme.
B7: Support communautaire | C7: Communauté active | D7: Présence d'une communauté d'utilisateurs et de développeurs contribuant au support et à l'évolution de la solution. | E7: Forum actif avec plus de 100 messages par mois, contributions régulières au code, et meetups organisés par les utilisateurs.
C8: Plateformes communautaires | D8: Existence de canaux de communication et d'entraide entre utilisateurs et développeurs. | E8: Stack Overflow tag dédié, canal Discord/Slack, liste de diffusion, et dépôt GitHub avec issue tracking actif.
B9: Technologie de développement | C9: Langage de programmation | D9: Langage(s) informatique(s) utilisé(s) pour implémenter la solution, pouvant influencer les performances, la portabilité et la facilité d'extension | E9: Java, Python, C++, JavaScript, etc.
A10: ENF2. Compatibilité et interopérabilité | B10: SGBD supportés | C10: PostgreSQL | D10: Implémentation de la solution sur différents systèmes de gestion de bases de données en assurant la compatibilité des fonctionnalités temporelles. | E10: Type Range pour la gestion des périodes temporelles.
C11: IBM Db2 | E11: Business Time et System Time pour la gestion du valid time et du transaction time.
C12: MS SQL
C13: MariaDB | E13: System-Versioned Tables.
C14: Oracle | E14: Flashback Data Archive.
A15: ENF3. Langage de requête supporté | D15: Langages de requête pris en charge par la solution pour interroger et manipuler les données temporelles, qu'il s'agisse de SQL et ses extensions temporelles ou de langages propriétaires spécifiques à l'outil. | E15: SQL:2011, TSQL, TF-ORM Query Language, etc.
A16: ENF4. Test et validation | B16: Tests fonctionnels | D16: Vérification que le modèle temporel implémenté se comporte correctement selon les scénarios attendus, en couvrant l'ensemble des opérations et règles d'intégrité temporelle. | E16: La modification d'un tuple génère une nouvelle version avec la bonne période de validité ou de transaction, que l'ancienne version reste accessible, et qu'une tentative d'insertion avec des périodes qui se chevauchent est rejetée par l'outil.
B17: Tests de performance | D17: Évaluation des temps de réponse lors de requêtes temporelles sur de grands volumes de données. | E17: Mesure du temps de réponse d'une requête temporelle de détection des anomalies temporelles utilisant fold/unfold et d'une autre utilisant les window functions.
